Workbook

Sheet README
B1: Manufacturing Plant Operating Model
B2: Meridian Home Appliances Pvt Ltd (fictional) · Plant 1, Chakan (Pune) · 15 products · 10 raw materials · 10 suppliers · 9 work centres · 12-month plan
B4: 1. What this workbook is
B5: A connected planning model of a mid-size Indian electrical home-appliance plant. Fifteen products (ceiling, pedestal, table and exhaust fans, an air cooler, mixer grinders, a kettle, an induction cooktop, a sandwich maker, a room heater, an immersion rod, an iron and a water pump) are built from ten raw materials bought from ten suppliers. Material flows through a press shop, aluminium die-casting, injection moulding, motor and heating-element winding and a powder-coating line into sub-assembly modules, then three final-assembly lines and packing. Change any blue input and unit costs, margins, material requirements, capacity loads, reorder status and supplier spend all recalculate.
B7: 2. Plant at a glance (live)
B8: Annual production | C8: =TEXT(Products!R18,"#,##0")&" units" -> 2,620,700 units
B9: Revenue (ex-GST) | C9: ="₹ "&TEXT(Products!S18*Assumptions!$B$20/Assumptions!$B$21,"#,##0.0")&" crore" -> ₹ 363.9 crore
B10: Raw-material spend | C10: ="₹ "&TEXT(Spend!M15*Assumptions!$B$20/Assumptions!$B$21,"#,##0.0")&" crore ("&TEXT(Spend!M15/Products!S18,"0.0%")&" of revenue)" -> ₹ 161.6 crore (44.4% of revenue)
B11: Gross margin | C11: =TEXT(Products!Q18,"0.0%")&" (after raw material, bought-out parts and conversion cost)" -> 29.6% (after raw material, bought-out parts and conversion cost)
B12: Peak capacity pressure | C12: =TEXT(MAX(Capacity!R18:R26),"0%")&" peak utilization; "&SUM(Capacity!T18:T26)&" work-centre months above 100%" -> 109% peak utilization; 5 work-centre months above 100%
B13: Model integrity | C13: =Checks!B3 -> ALL 33 CHECKS PASS
B15: 3. How the numbers flow
B16: Cost: Products x BOM -> raw-material cost per unit. Add bought-out parts and conversion cost (Routing minutes x WorkCentres rates) -> standard cost -> margin vs selling price.
B17: Materials: Demand_Plan (units by month) x BOM_Matrix (gross kg per unit, after process yield) -> MRP (kg by month).
B18: Purchasing: MRP x Sourcing split (primary / secondary / sole source) x effective price -> Spend matrix (₹ lakh by supplier and material) -> Suppliers (spend share, watch-list flags).
B19: Capacity: Demand_Plan x Routing minutes / 60 -> load hours by work centre and month -> Capacity (utilization vs effective hours after OEE).
B20: Inventory: MRP usage + weighted lead time + safety days -> reorder point, status (REORDER NOW / WATCH / OK), suggested order quantity and ABC class.
B21: Assurance: Checks proves the totals tie out by two independent routes, and that IDs, shares and ranges are valid.
B23: 4. Sheet guide (click a name to jump)
B24: Sheet | C24: Type | D24: What it holds
B25: Dashboard | C25: Output | D25: KPI tiles, capacity heat map, live takeaways and six charts (revenue by family, utilization, spend by material and supplier, margins, inventory cover).
B26: Assumptions | C26: Input | D26: Global parameters and the demand multiplier lever; thresholds for flags, ABC classes and capacity colours.
B27: Products | C27: Input + calc | D27: 15 products P01-P15: spec, final-assembly line, batch size, bought-out parts, selling price, and the cost / margin / revenue roll-up.
B28: RawMaterials | C28: Input + calc | D28: 10 materials RW01-RW10: specification, yield, safety days, price lever, weighted price and lead time, price basis notes.
B29: Suppliers | C29: Input + calc | D29: 10 suppliers S01-S10: location, type, delivery / quality / financial inputs; spend share and automatic watch-list reasons.
B30: Sourcing | C30: Input + calc | D30: 18 supplier-material links: share of requirement, quoted and effective price, lead time, MOQ, transport; annual volume and spend.
B31: BOM | C31: Input + calc | D31: 102 bill-of-material lines by assembly module: net kg per unit, process yield, gross kg, cost and loss.
B32: BOM_Matrix | C32: Calc | D32: Product x material views of net kg, gross kg and cost per unit, plus cost by assembly module.
B33: WorkCentres | C33: Input + calc | D33: 9 work centres: units, shifts, OEE, cost rate; effective capacity in hours per month.
B34: Routing | C34: Input + calc | D34: Standard minutes per unit at each work centre (including each product's own final-assembly line) and the conversion-cost build-up.
B35: Demand_Plan | C35: Input + calc | D35: Seasonality indices and the 12-month production plan in units, revenue by month and by product family.
... B40: Checks | C40: Output | D40: 33 live integrity checks.
B42: 5. Colour and format conventions
B43: Blue text | C43: Hard-coded input or assumption - safe to change.
B44: Black text | C44: Formula - do not overwrite.
B45: Green text | C45: Value pulled from another sheet.
B46: Yellow fill | C46: Scenario lever (demand multiplier, per-material price change).
B47: Units: money tables are in ₹ lakh (1 lakh = 100,000) and dashboard headline figures in ₹ crore (1 crore = 10,000,000); prices are ex-GST; materials are in kg; time is in minutes per unit or hours per month. Tab colours: blue = input sheets, green = calculation sheets, orange = dashboard, yellow = assumptions, grey = documentation and checks. The heat-map and status colours (red / amber / green / grey) are always paired with text so colour is never the only signal.
B49: 6. Try these what-ifs
B50: • Assumptions!B10: set the demand multiplier to 1.15 - watch the capacity heat map, the reorder list and the supplier spend shares change.
...

Sheet Dashboard
A1: =Assumptions!B5&" | "&Assumptions!B6 -> Meridian Home Appliances Pvt Ltd | Plant 1, Chakan (Pune), Maharashtra
A2: ="Plant operating dashboard · plan "&TEXT(Demand_Plan!E5,"mmm-yy")&" to "&TEXT(Demand_Plan!P5,"mmm-yy")&" · stock as of "&TEXT(Assumptions!B7,"dd-mmm-yyyy")&" · fictional company and suppliers, illustrative figures" -> Plant operating dashboard · plan Nov-26 to Oct-27 · stock as of 20-Oct-2026 · fictional company and suppliers, illustrative figures
B4: Annual production | D4: Revenue (ex-GST) | F4: Gross margin | H4: Raw-material spend | J4: Material yield loss | L4: Tightest work centre (peak) | N4: Overloaded work-centre months
B5: =Products!R18 -> 2620700 | D5: =Products!S18*Assumptions!$B$20/Assumptions!$B$21 -> 363.87617 | F5: =Products!Q18 -> 0.29587649 | H5: =Spend!M15*Assumptions!$B$20/Assumptions!$B$21 -> 161.57992 | J5: =MRP!V15 -> 0.11975655 | L5: =MAX(Capacity!R18:R26) -> 1.0877297 | N5: =SUM(Capacity!T18:T26) -> 5
B6: ="units across 15 products" -> units across 15 products | D6: ="₹ "&TEXT(Products!S18,"#,##0")&" lakh" -> ₹ 36,388 lakh | F6: ="₹ "&TEXT(Products!T18*Assumptions!$B$20/Assumptions!$B$21,"#,##0.0")&" cr gross profit" -> ₹ 107.7 cr gross profit | H6: =TEXT(Spend!M15/Products!S18,"0.0%")&" of revenue" -> 44.4% of revenue | J6: =TEXT(MRP!U15/1000,"#,##0")&" tonnes of scrap a year" -> 1,028 tonnes of scrap a year | L6: =INDEX(WorkCentres!$C$2:$C$10,MATCH(INDEX(Capacity!A18:A26,MATCH(MAX(Capacity!R18:R26),Capacity!R18:R26,0)),WorkCentres!$A$2:$A$10,0))&" - "&TEXT(INDEX(Capacity!S18:S26,MATCH(MAX(Capacity!R18:R26),Capacity!R18:R26,0)),"mmm-yy") -> FA-1 Fans & coolers - Apr-27 | N6: ="of "&COUNT(Capacity!E18:P26)&" (9 centres x 12 months)" -> of 108 (9 centres x 12 months)
B8: Suppliers on watch-list | D8: Largest supplier share | F8: Import share of RM spend | H8: Sole-sourced materials | J8: Materials to reorder now | L8: RM stock value | N8: Model integrity checks
B9: =COUNTIF(Suppliers!T2:T11,">0") -> 6 | D9: =MAX(Suppliers!R2:R11) -> 0.32747839 | F9: =SUMIF(Suppliers!S2:S11,"Import",Suppliers!Q2:Q11)/SUM(Suppliers!Q2:Q11) -> 0.04799131 | H9: =COUNTIF(RawMaterials!R2:R11,"Yes") -> 2 | J9: =COUNTIF(Inventory!O5:O14,"REORDER NOW") -> 2 | L9: =Inventory!T15*Assumptions!$B$20/Assumptions!$B$21 -> 7.189056 | N9: =COUNTIF(Checks!C5:C37,"PASS")&" / "&COUNTA(Checks!C5:C37) -> 33 / 33
B10: ="of "&COUNTA(Suppliers!A2:A11)&" suppliers" -> of 10 suppliers | D10: =INDEX(Suppliers!C2:C11,MATCH(MAX(Suppliers!R2:R11),Suppliers!R2:R11,0))&" (share of RM spend)" -> Vadodara Wires (share of RM spend) | F10: =COUNTIF(Suppliers!S2:S11,"Import")&" import supplier(s)" -> 1 import supplier(s) | H10: ="of "&COUNTA(RawMaterials!A2:A11)&" raw materials" -> of 10 raw materials | J10: =COUNTIF(Inventory!O5:O14,"WATCH")&" more on watch" -> 1 more on watch | L10: =TEXT(Inventory!E19,"0")&" days of annual spend" -> 16 days of annual spend | N10: =IF(COUNTIF(Checks!C5:C37,"PASS")=ROWS(Checks!C5:C37),"all checks pass","see Checks sheet") -> all checks pass
B12: What the model says right now (live text)
B13: ="Cost: "&INDEX(Spend!$C$3:$L$3,MATCH(MAX(Spend!$C$16:$L$16),Spend!$C$16:$L$16,0))&" is the biggest cost line at "&TEXT(MAX(Spend!$C$16:$L$16),"0%")&" of raw-material spend, and "&INDEX(Suppliers!$C$2:$C$11,MATCH(MAX(Suppliers!$R$2:$R$11),Suppliers!$R$2:$R$11,0))&" alone supplies "&TEXT(MAX(Suppliers!$R$2:$R$11),"0%")&" of the total - a price or delivery shock there moves the plant margin." -> Cost: Copper winding wire is the biggest cost line at 41% of raw-material spend, and Vadodara Wires alone supplies 33% of the total - a price or delivery shock there moves the plant margin.
B14: ="Capacity: "&INDEX(WorkCentres!$C$2:$C$10,MATCH(INDEX(Capacity!$A$18:$A$26,MATCH(MAX(Capacity!$R$18:$R$26),Capacity!$R$18:$R$26,0)),WorkCentres!$A$2:$A$10,0))&" is the tightest centre at "&TEXT(MAX(Capacity!$R$18:$R$26),"0%")&" in "&TEXT(INDEX(Capacity!$S$18:$S$26,MATCH(MAX(Capacity!$R$18:$R$26),Capacity!$R$18:$R$26,0)),"mmm-yy")&IF(SUM(Capacity!$T$18:$T$26)>0,"; "&SUM(Capacity!$T$18:$T$26)&" work-centre months exceed 100% and need a 3rd shift, overtime or off-season pre-build.","; no work centre exceeds 100%.") -> Capacity: FA-1 Fans & coolers is the tightest centre at 109% in Apr-27; 5 work-centre months exceed 100% and need a 3rd shift, overtime or off-season pre-build.
B15: ="Supply: "&COUNTIF(Inventory!$O$5:$O$14,"REORDER NOW")&" material(s) at or below the reorder point today (suggested orders worth ₹"&TEXT(Inventory!$S$15,"#,##0")&" lakh), "&COUNTIF(Inventory!$O$5:$O$14,"WATCH")&" more on watch; "&COUNTIF(RawMaterials!$R$2:$R$11,"Yes")&" material(s) depend on a single supplier." -> Supply: 2 material(s) at or below the reorder point today (suggested orders worth ₹221 lakh), 1 more on watch; 2 material(s) depend on a single supplier.
B17: Capacity heat map - utilization by work centre and month (red > 100%, amber >= 85%, green 50-85%, grey < 50%)
B18: Work centre | D18: =Capacity!E$17 -> 46327 | E18: =Capacity!F$17 -> 46357 | F18: =Capacity!G$17 -> 46388 | G18: =Capacity!H$17 -> 46419 | H18: =Capacity!I$17 -> 46447 | I18: =Capacity!J$17 -> 46478 | J18: =Capacity!K$17 -> 46508 | K18: =Capacity!L$17 -> 46539 | ... O18: =Capacity!P$17 -> 46661
B19: =INDEX(WorkCentres!$C$2:$C$10,MATCH(Capacity!$A18,WorkCentres!$A$2:$A$10,0)) -> Press shop | D19: =Capacity!E18 -> 0.62029724 | E19: =Capacity!F18 -> 0.56905573 | F19: =Capacity!G18 -> 0.5684345 | G19: =Capacity!H18 -> 0.67691282 | H19: =Capacity!I18 -> 0.87999609 | I19: =Capacity!J18 -> 0.96738711 | J19: =Capacity!K18 -> 0.92286706 | K19: =Capacity!L18 -> 0.77546932 | ... O19: =Capacity!P18 -> 0.73935082
B20: =INDEX(WorkCentres!$C$2:$C$10,MATCH(Capacity!$A19,WorkCentres!$A$2:$A$10,0)) -> Al die-casting | D20: =Capacity!E19 -> 0.69376018 | E20: =Capacity!F19 -> 0.61277218 | F20: =Capacity!G19 -> 0.60168905 | G20: =Capacity!H19 -> 0.71789021 | H20: =Capacity!I19 -> 0.91447904 | I20: =Capacity!J19 -> 0.98853276 | J20: =Capacity!K19 -> 0.94891127 | K20: =Capacity!L19 -> 0.82258598 | ... O20: =Capacity!P19 -> 0.80112943
B21: =INDEX(WorkCentres!$C$2:$C$10,MATCH(Capacity!$A20,WorkCentres!$A$2:$A$10,0)) -> Injection moulding | D21: =Capacity!E20 -> 0.72080329 | E21: =Capacity!F20 -> 0.69040256 | F21: =Capacity!G20 -> 0.67299763 | G21: =Capacity!H20 -> 0.71801132 | H21: =Capacity!I20 -> 0.92942875 | I21: =Capacity!J20 -> 1.0158712 | J21: =Capacity!K20 -> 0.95141393 | K21: =Capacity!L20 -> 0.75743273 | ... O21: =Capacity!P20 -> 0.70906784
B22: =INDEX(WorkCentres!$C$2:$C$10,MATCH(Capacity!$A21,WorkCentres!$A$2:$A$10,0)) -> Winding & motor | D22: =Capacity!E21 -> 0.66680007 | E22: =Capacity!F21 -> 0.63171585 | F22: =Capacity!G21 -> 0.63028192 | G22: =Capacity!H21 -> 0.69640915 | H22: =Capacity!I21 -> 0.84516083 | I22: =Capacity!J21 -> 0.90645402 | J22: =Capacity!K21 -> 0.86379227 | K22: =Capacity!L21 -> 0.73602168 | ... O22: =Capacity!P21 -> 0.74934159
B23: =INDEX(WorkCentres!$C$2:$C$10,MATCH(Capacity!$A22,WorkCentres!$A$2:$A$10,0)) -> Powder coating | D23: =Capacity!E22 -> 0.479468 | E23: =Capacity!F22 -> 0.44483139 | F23: =Capacity!G22 -> 0.46714059 | G23: =Capacity!H22 -> 0.60024244 | H23: =Capacity!I22 -> 0.86196033 | I23: =Capacity!J22 -> 0.98989152 | J23: =Capacity!K22 -> 0.94126671 | K23: =Capacity!L22 -> 0.76673104 | ... O23: =Capacity!P22 -> 0.63051309
B24: =INDEX(WorkCentres!$C$2:$C$10,MATCH(Capacity!$A23,WorkCentres!$A$2:$A$10,0)) -> FA-1 Fans & coolers | D24: =Capacity!E23 -> 0.35301402 | E24: =Capacity!F23 -> 0.29874537 | F24: =Capacity!G23 -> 0.3220554 | G24: =Capacity!H23 -> 0.52681081 | H24: =Capacity!I23 -> 0.91071918 | I24: =Capacity!J23 -> 1.0877297 | J24: =Capacity!K23 -> 1.0248697 | K24: =Capacity!L23 -> 0.79354775 | ... O24: =Capacity!P23 -> 0.54915673
B25: =INDEX(WorkCentres!$C$2:$C$10,MATCH(Capacity!$A24,WorkCentres!$A$2:$A$10,0)) -> FA-2 Kitchen | D25: =Capacity!E24 -> 0.89547197 | E25: =Capacity!F24 -> 0.79213015 | F25: =Capacity!G24 -> 0.71628331 | G25: =Capacity!H24 -> 0.70795626 | H25: =Capacity!I24 -> 0.63474108 | I25: =Capacity!J24 -> 0.56199723 | J25: =Capacity!K24 -> 0.55649824 | K25: =Capacity!L24 -> 0.57008861 | ... O25: =Capacity!P24 -> 0.8935866
B26: =INDEX(WorkCentres!$C$2:$C$10,MATCH(Capacity!$A25,WorkCentres!$A$2:$A$10,0)) -> FA-3 Heating & pumps | D26: =Capacity!E25 -> 0.90379902 | E26: =Capacity!F25 -> 1.0312298 | F26: =Capacity!G25 -> 1.0553019 | G26: =Capacity!H25 -> 0.79168687 | H26: =Capacity!I25 -> 0.55786738 | I26: =Capacity!J25 -> 0.47319409 | J26: =Capacity!K25 -> 0.44626023 | K26: =Capacity!L25 -> 0.44390352 | ... O26: =Capacity!P25 -> 0.67772301
B27: =INDEX(WorkCentres!$C$2:$C$10,MATCH(Capacity!$A26,WorkCentres!$A$2:$A$10,0)) -> Packing & dispatch | D27: =Capacity!E26 -> 0.66617194 | E27: =Capacity!F26 -> 0.6362832 | F27: =Capacity!G26 -> 0.63185187 | G27: =Capacity!H26 -> 0.69063532 | H27: =Capacity!I26 -> 0.85001912 | I27: =Capacity!J26 -> 0.91326425 | J27: =Capacity!K26 -> 0.86543773 | K27: =Capacity!L26 -> 0.72824853 | ... O27: =Capacity!P26 -> 0.73689115
B30: Charts
B85: Where a blue cover bar is shorter than its orange reorder-point bar, the material has hit its reorder trigger (quantities are on the Inventory sheet).
B92: Chart data (formulas that feed the charts above - do not overwrite)
B94: Raw-material spend, ranked (₹ lakh) | G94: Supplier spend, ranked (₹ lakh)
B95: Material | D95: ₹ lakh | E95: rank key | G95: Supplier | I95: ₹ lakh | J95: rank key
B96: =INDEX(Spend!$C$3:$L$3,MATCH(SMALL($E$96:$E$105,1),$E$96:$E$105,0)) -> Powder coating | D96: =INDEX(Spend!$C$15:$L$15,MATCH(SMALL($E$96:$E$105,1),$E$96:$E$105,0)) -> 314.24756 | E96: =Spend!C$15+ROW()/1000000000 -> 1255.1539 | G96: =INDEX(Suppliers!$C$2:$C$11,MATCH(SMALL($J$96:$J$105,1),$J$96:$J$105,0)) -> Ahmedabad Coatings | I96: =INDEX(Spend!$M$5:$M$14,MATCH(SMALL($J$96:$J$105,1),$J$96:$J$105,0)) -> 314.24756 | J96: =Spend!M5+ROW()/1000000000 -> 1540.7753
B97: =INDEX(Spend!$C$3:$L$3,MATCH(SMALL($E$96:$E$105,2),$E$96:$E$105,0)) -> Nichrome wire | D97: =INDEX(Spend!$C$15:$L$15,MATCH(SMALL($E$96:$E$105,2),$E$96:$E$105,0)) -> 458.43417 | E97: =Spend!D$15+ROW()/1000000000 -> 1560.2804 | G97: =INDEX(Suppliers!$C$2:$C$11,MATCH(SMALL($J$96:$J$105,2),$J$96:$J$105,0)) -> Pacific Plastics (TW) | I97: =INDEX(Spend!$M$5:$M$14,MATCH(SMALL($J$96:$J$105,2),$J$96:$J$105,0)) -> 775.4432 | J97: =Spend!M6+ROW()/1000000000 -> 1813.1851
B98: =INDEX(Spend!$C$3:$L$3,MATCH(SMALL($E$96:$E$105,3),$E$96:$E$105,0)) -> PP granules | D98: =INDEX(Spend!$C$15:$L$15,MATCH(SMALL($E$96:$E$105,3),$E$96:$E$105,0)) -> 769.40391 | E98: =Spend!E$15+ROW()/1000000000 -> 2266.4944 | G98: =INDEX(Suppliers!$C$2:$C$11,MATCH(SMALL($J$96:$J$105,3),$J$96:$J$105,0)) -> Bhiwandi Packaging | I98: =INDEX(Spend!$M$5:$M$14,MATCH(SMALL($J$96:$J$105,3),$J$96:$J$105,0)) -> 795.32526 | J98: =Spend!M7+ROW()/1000000000 -> 1453.5033
B99: =INDEX(Spend!$C$3:$L$3,MATCH(SMALL($E$96:$E$105,4),$E$96:$E$105,0)) -> Corrugated cartons | D99: =INDEX(Spend!$C$15:$L$15,MATCH(SMALL($E$96:$E$105,4),$E$96:$E$105,0)) -> 795.32526 | E99: =Spend!F$15+ROW()/1000000000 -> 6664.6628 | G99: =INDEX(Suppliers!$C$2:$C$11,MATCH(SMALL($J$96:$J$105,4),$J$96:$J$105,0)) -> Mumbai Polymer | I99: =INDEX(Spend!$M$5:$M$14,MATCH(SMALL($J$96:$J$105,4),$J$96:$J$105,0)) -> 1066.9995 | J99: =Spend!M8+ROW()/1000000000 -> 1417.5745
B100: =INDEX(Spend!$C$3:$L$3,MATCH(SMALL($E$96:$E$105,5),$E$96:$E$105,0)) -> SS304 sheet | D100: =INDEX(Spend!$C$15:$L$15,MATCH(SMALL($E$96:$E$105,5),$E$96:$E$105,0)) -> 1000.9508 | E100: =Spend!G$15+ROW()/1000000000 -> 769.40391 | G100: =INDEX(Suppliers!$C$2:$C$11,MATCH(SMALL($J$96:$J$105,5),$J$96:$J$105,0)) -> Bharat Metal Traders | I100: =INDEX(Spend!$M$5:$M$14,MATCH(SMALL($J$96:$J$105,5),$J$96:$J$105,0)) -> 1417.5745 | J100: =Spend!M9+ROW()/1000000000 -> 5291.3933
B101: =INDEX(Spend!$C$3:$L$3,MATCH(SMALL($E$96:$E$105,6),$E$96:$E$105,0)) -> ABS granules | D101: =INDEX(Spend!$C$15:$L$15,MATCH(SMALL($E$96:$E$105,6),$E$96:$E$105,0)) -> 1073.0388 | E101: =Spend!H$15+ROW()/1000000000 -> 1073.0388 | G101: =INDEX(Suppliers!$C$2:$C$11,MATCH(SMALL($J$96:$J$105,6),$J$96:$J$105,0)) -> Deccan Aluminium | I101: =INDEX(Spend!$M$5:$M$14,MATCH(SMALL($J$96:$J$105,6),$J$96:$J$105,0)) -> 1453.5033 | J101: =Spend!M10+ROW()/1000000000 -> 1689.545
B102: =INDEX(Spend!$C$3:$L$3,MATCH(SMALL($E$96:$E$105,7),$E$96:$E$105,0)) -> CRNGO steel coil | D102: =INDEX(Spend!$C$15:$L$15,MATCH(SMALL($E$96:$E$105,7),$E$96:$E$105,0)) -> 1255.1539 | E102: =Spend!I$15+ROW()/1000000000 -> 1000.9508 | G102: =INDEX(Suppliers!$C$2:$C$11,MATCH(SMALL($J$96:$J$105,7),$J$96:$J$105,0)) -> Kalinga Steels | I102: =INDEX(Spend!$M$5:$M$14,MATCH(SMALL($J$96:$J$105,7),$J$96:$J$105,0)) -> 1540.7753 | J102: =Spend!M11+ROW()/1000000000 -> 1066.9995
B103: =INDEX(Spend!$C$3:$L$3,MATCH(SMALL($E$96:$E$105,8),$E$96:$E$105,0)) -> CRCA steel sheet | D103: =INDEX(Spend!$C$15:$L$15,MATCH(SMALL($E$96:$E$105,8),$E$96:$E$105,0)) -> 1560.2804 | E103: =Spend!J$15+ROW()/1000000000 -> 458.43417 | G103: =INDEX(Suppliers!$C$2:$C$11,MATCH(SMALL($J$96:$J$105,8),$J$96:$J$105,0)) -> Coimbatore Magnet | I103: =INDEX(Spend!$M$5:$M$14,MATCH(SMALL($J$96:$J$105,8),$J$96:$J$105,0)) -> 1689.545 | J103: =Spend!M12+ROW()/1000000000 -> 775.4432
B104: =INDEX(Spend!$C$3:$L$3,MATCH(SMALL($E$96:$E$105,9),$E$96:$E$105,0)) -> Aluminium ADC12 | D104: =INDEX(Spend!$C$15:$L$15,MATCH(SMALL($E$96:$E$105,9),$E$96:$E$105,0)) -> 2266.4944 | E104: =Spend!K$15+ROW()/1000000000 -> 314.24756 | G104: =INDEX(Suppliers!$C$2:$C$11,MATCH(SMALL($J$96:$J$105,9),$J$96:$J$105,0)) -> Pune Coil Proc. | I104: =INDEX(Spend!$M$5:$M$14,MATCH(SMALL($J$96:$J$105,9),$J$96:$J$105,0)) -> 1813.1851 | J104: =Spend!M13+ROW()/1000000000 -> 314.24756
B105: =INDEX(Spend!$C$3:$L$3,MATCH(SMALL($E$96:$E$105,10),$E$96:$E$105,0)) -> Copper winding wire | D105: =INDEX(Spend!$C$15:$L$15,MATCH(SMALL($E$96:$E$105,10),$E$96:$E$105,0)) -> 6664.6628 | E105: =Spend!L$15+ROW()/1000000000 -> 795.32526 | G105: =INDEX(Suppliers!$C$2:$C$11,MATCH(SMALL($J$96:$J$105,10),$J$96:$J$105,0)) -> Vadodara Wires | I105: =INDEX(Spend!$M$5:$M$14,MATCH(SMALL($J$96:$J$105,10),$J$96:$J$105,0)) -> 5291.3933 | J105: =Spend!M14+ROW()/1000000000 -> 795.32526
B108: Work-centre utilization | H108: Monthly revenue by family (₹ lakh)
B109: Work centre | D109: Average | E109: Peak month | F109: 100% line | H109: Family | J109: =TEXT(Demand_Plan!E$5,"mmm-yy") -> Nov-26 | K109: =TEXT(Demand_Plan!F$5,"mmm-yy") -> Dec-26 | L109: =TEXT(Demand_Plan!G$5,"mmm-yy") -> Jan-27 | M109: =TEXT(Demand_Plan!H$5,"mmm-yy") -> Feb-27 | N109: =TEXT(Demand_Plan!I$5,"mmm-yy") -> Mar-27 | O109: =TEXT(Demand_Plan!J$5,"mmm-yy") -> Apr-27 | P109: =TEXT(Demand_Plan!K$5,"mmm-yy") -> May-27 | Q109: =TEXT(Demand_Plan!L$5,"mmm-yy") -> Jun-27 | ... U109: =TEXT(Demand_Plan!P$5,"mmm-yy") -> Oct-27
...

Sheet Assumptions
A1: Assumptions & scenario levers
A2: Global parameters that drive every calculation sheet. Blue = input. Yellow = scenario lever you can change to test a what-if.
A4: Parameter | B4: Value | C4: Unit | D4: Where it is used / note
A5: Company (fictional) | B5: Meridian Home Appliances Pvt Ltd | D5: Fictional company created for this model; supplier names are fictional too.
A6: Plant | B6: Plant 1, Chakan (Pune), Maharashtra | D6: Single-plant, make-to-forecast operating model.
A7: Inventory snapshot date | B7: 46315 | C7: date | D7: Stock and on-order quantities on the Inventory sheet are as of this date.
A8: Plan start month | B8: 46327 | C8: month | D8: First of 12 planning months (Demand_Plan, MRP, Capacity headers follow from this).
A9: Working days per month | B9: 26 | C9: days | D9: Capacity: every work centre runs this many days a month (6-day week).
A10: Demand multiplier | B10: 1 | C10: x | D10: LEVER. Scales every product's demand: 1.10 = +10%. Flows to MRP, Capacity, Spend, Inventory.
A11: Order-up-to cover | B11: 30 | C11: days | D11: Inventory: order-up-to level = reorder point + this many days of usage.
A12: WATCH buffer above reorder point | B12: 0.15 | C12: % | D12: Inventory: status is WATCH when position is within this % above the reorder point.
A13: ABC class A cut-off (cumulative spend) | B13: 0.8 | C13: % | D13: Materials inside the first 80% of cumulative spend are class A.
A14: ABC class B cut-off (cumulative spend) | B14: 0.95 | C14: % | D14: Next band up to 95% is class B; the rest is class C.
A15: Supplier flag: on-time delivery below | B15: 0.9 | C15: % | D15: Suppliers: low on-time delivery flag.
A16: Supplier flag: financial health score below | B16: 65 | C16: score | D16: Suppliers: weak financial score flag (scale 0-100).
A17: Supplier flag: share of total RM spend at or above | B17: 0.2 | C17: % | D17: Suppliers: concentration flag.
A18: Capacity: TIGHT at or above | B18: 0.85 | C18: % | D18: Capacity status and heat-map colour (amber).
... A21: Rupees per crore | B21: 10000000 | C21: ₹ | D21: Unit conversion: dashboard KPIs are shown in ₹ crore (1 crore = 10,000,000).
A23: Per-material price changes are set on RawMaterials (column H, yellow). Selling prices are on Products (column O).

Sheet Products
A1: Product ID | B1: Product | C1: Family | D1: Specification | E1: Final assembly WC | F1: Final assembly line | G1: Batch / lot size (units) | H1: Warranty (months) | I1: Base demand (units / month) | J1: Bought-out parts (₹ / unit) | K1: Key bought-out parts | L1: Raw-material cost (₹ / unit) | M1: Conversion cost (₹ / unit) | N1: Standard cost (₹ / unit) | O1: Selling price, ex-GST (₹ / unit) | P1: Gross margin (₹ / unit) | Q1: Gross margin (%) | R1: Annual units (plan) | S1: Annual revenue (₹ lakh) | T1: Annual gross profit (₹ lakh) | U1: RM share of standard cost
A2: P01 | B2: Ceiling Fan 1200 mm - Induction | C2: Fans & Cooling | D2: 1200 mm sweep, 75 W induction motor, 3 blades | E2: WC06 | F2: =INDEX(WorkCentres!$C$2:$C$10,MATCH(E2,WorkCentres!$A$2:$A$10,0)) -> FA-1 Fans & coolers | G2: 500 | H2: 24 | I2: 38000 | J2: 235 | K2: Ball bearings, capacitor, regulator, shaft and down-rod, fasteners | L2: =SUMIFS(BOM!$K$2:$K$400,BOM!$B$2:$B$400,$A2) -> 1067.5833 | M2: =INDEX(Routing!$L$25:$L$39,MATCH($A2,Routing!$A$25:$A$39,0)) -> 165.965 | N2: =L2+J2+M2 -> 1468.5483 | O2: 2010 | P2: =O2-N2 -> 541.45169 | Q2: =IF(O2=0,0,P2/O2) -> 0.26937895 | R2: =INDEX(Demand_Plan!$Q$24:$Q$38,MATCH($A2,Demand_Plan!$A$24:$A$38,0)) -> 458500 | S2: =R2*O2/Assumptions!$B$20 -> 9215.85 | T2: =R2*P2/Assumptions!$B$20 -> 2482.556 | U2: =IF(N2=0,0,L2/N2) -> 0.72696506
A3: P02 | B3: Ceiling Fan 1200 mm - BLDC | C3: Fans & Cooling | D3: 1200 mm sweep, 28 W BLDC motor, 3 blades | E3: WC06 | F3: =INDEX(WorkCentres!$C$2:$C$10,MATCH(E3,WorkCentres!$A$2:$A$10,0)) -> FA-1 Fans & coolers | G3: 250 | H3: 36 | I3: 12000 | J3: 650 | K3: BLDC driver PCB and remote receiver, magnets, bearings, fasteners | L3: =SUMIFS(BOM!$K$2:$K$400,BOM!$B$2:$B$400,$A3) -> 874.44226 | M3: =INDEX(Routing!$L$25:$L$39,MATCH($A3,Routing!$A$25:$A$39,0)) -> 157.73 | N3: =L3+J3+M3 -> 1682.1723 | O3: 2590 | P3: =O3-N3 -> 907.82774 | Q3: =IF(O3=0,0,P3/O3) -> 0.35051264 | R3: =INDEX(Demand_Plan!$Q$24:$Q$38,MATCH($A3,Demand_Plan!$A$24:$A$38,0)) -> 145000 | S3: =R3*O3/Assumptions!$B$20 -> 3755.5 | T3: =R3*P3/Assumptions!$B$20 -> 1316.3502 | U3: =IF(N3=0,0,L3/N3) -> 0.5198292
A4: P03 | B4: Pedestal Fan 400 mm | C4: Fans & Cooling | D4: 400 mm sweep, 3-speed, oscillating, height-adjustable | E4: WC06 | F4: =INDEX(WorkCentres!$C$2:$C$10,MATCH(E4,WorkCentres!$A$2:$A$10,0)) -> FA-1 Fans & coolers | G4: 250 | H4: 24 | I4: 9000 | J4: 310 | K4: Bearings, capacitor, guard grills, oscillation gearbox, switch, cord | L4: =SUMIFS(BOM!$K$2:$K$400,BOM!$B$2:$B$400,$A4) -> 782.38259 | M4: =INDEX(Routing!$L$25:$L$39,MATCH($A4,Routing!$A$25:$A$39,0)) -> 155.87 | N4: =L4+J4+M4 -> 1248.2526 | O4: 1760 | P4: =O4-N4 -> 511.74741 | Q4: =IF(O4=0,0,P4/O4) -> 0.29076557 | R4: =INDEX(Demand_Plan!$Q$24:$Q$38,MATCH($A4,Demand_Plan!$A$24:$A$38,0)) -> 109500 | S4: =R4*O4/Assumptions!$B$20 -> 1927.2 | T4: =R4*P4/Assumptions!$B$20 -> 560.36341 | U4: =IF(N4=0,0,L4/N4) -> 0.62678227
A5: P04 | B5: Table Fan 400 mm | C5: Fans & Cooling | D5: 400 mm sweep, 3-speed, oscillating | E5: WC06 | F5: =INDEX(WorkCentres!$C$2:$C$10,MATCH(E5,WorkCentres!$A$2:$A$10,0)) -> FA-1 Fans & coolers | G5: 500 | H5: 24 | I5: 14000 | J5: 190 | K5: Bearings, capacitor, guard grills, oscillation gearbox, switch, cord | L5: =SUMIFS(BOM!$K$2:$K$400,BOM!$B$2:$B$400,$A5) -> 554.98026 | M5: =INDEX(Routing!$L$25:$L$39,MATCH($A5,Routing!$A$25:$A$39,0)) -> 118.56 | N5: =L5+J5+M5 -> 863.54026 | O5: 1215 | P5: =O5-N5 -> 351.45974 | Q5: =IF(O5=0,0,P5/O5) -> 0.28926728 | R5: =INDEX(Demand_Plan!$Q$24:$Q$38,MATCH($A5,Demand_Plan!$A$24:$A$38,0)) -> 171000 | S5: =R5*O5/Assumptions!$B$20 -> 2077.65 | T5: =R5*P5/Assumptions!$B$20 -> 600.99616 | U5: =IF(N5=0,0,L5/N5) -> 0.64268024
A6: P05 | B6: Exhaust Fan 230 mm | C6: Fans & Cooling | D6: 230 mm (9 in) sweep, 55 W, with shutter | E6: WC06 | F6: =INDEX(WorkCentres!$C$2:$C$10,MATCH(E6,WorkCentres!$A$2:$A$10,0)) -> FA-1 Fans & coolers | G6: 500 | H6: 24 | I6: 16000 | J6: 95 | K6: Bearings, capacitor, shutter hardware, cord | L6: =SUMIFS(BOM!$K$2:$K$400,BOM!$B$2:$B$400,$A6) -> 315.33339 | M6: =INDEX(Routing!$L$25:$L$39,MATCH($A6,Routing!$A$25:$A$39,0)) -> 85.7 | N6: =L6+J6+M6 -> 496.03339 | O6: 710 | P6: =O6-N6 -> 213.96661 | Q6: =IF(O6=0,0,P6/O6) -> 0.30136142 | R6: =INDEX(Demand_Plan!$Q$24:$Q$38,MATCH($A6,Demand_Plan!$A$24:$A$38,0)) -> 195000 | S6: =R6*O6/Assumptions!$B$20 -> 1384.5 | T6: =R6*P6/Assumptions!$B$20 -> 417.23489 | U6: =IF(N6=0,0,L6/N6) -> 0.63571001
A7: P06 | B7: Personal Air Cooler 30 L | C7: Fans & Cooling | D7: 30 L tank, 3-speed blower, honeycomb pads | E7: WC06 | F7: =INDEX(WorkCentres!$C$2:$C$10,MATCH(E7,WorkCentres!$A$2:$A$10,0)) -> FA-1 Fans & coolers | G7: 100 | H7: 24 | I7: 6500 | J7: 480 | K7: Water pump, honeycomb pads, castors, float valve, switch, cord | L7: =SUMIFS(BOM!$K$2:$K$400,BOM!$B$2:$B$400,$A7) -> 898.3293 | M7: =INDEX(Routing!$L$25:$L$39,MATCH($A7,Routing!$A$25:$A$39,0)) -> 217.98 | N7: =L7+J7+M7 -> 1596.3093 | O7: 2215 | P7: =O7-N7 -> 618.6907 | Q7: =IF(O7=0,0,P7/O7) -> 0.2793186 | R7: =INDEX(Demand_Plan!$Q$24:$Q$38,MATCH($A7,Demand_Plan!$A$24:$A$38,0)) -> 78300 | S7: =R7*O7/Assumptions!$B$20 -> 1734.345 | T7: =R7*P7/Assumptions!$B$20 -> 484.43482 | U7: =IF(N7=0,0,L7/N7) -> 0.56275391
A8: P07 | B8: Mixer Grinder 500 W | C8: Kitchen Appliances | D8: 500 W universal motor, 3 stainless-steel jars | E8: WC07 | F8: =INDEX(WorkCentres!$C$2:$C$10,MATCH(E8,WorkCentres!$A$2:$A$10,0)) -> FA-2 Kitchen | G8: 500 | H8: 24 | I8: 18000 | J8: 165 | K8: Jar lids and gaskets, switch, overload protector, cord, rubber feet | L8: =SUMIFS(BOM!$K$2:$K$400,BOM!$B$2:$B$400,$A8) -> 771.03894 | M8: =INDEX(Routing!$L$25:$L$39,MATCH($A8,Routing!$A$25:$A$39,0)) -> 138.31167 | N8: =L8+J8+M8 -> 1074.3506 | O8: 1555 | P8: =O8-N8 -> 480.64939 | Q8: =IF(O8=0,0,P8/O8) -> 0.30909929 | R8: =INDEX(Demand_Plan!$Q$24:$Q$38,MATCH($A8,Demand_Plan!$A$24:$A$38,0)) -> 218500 | S8: =R8*O8/Assumptions!$B$20 -> 3397.675 | T8: =R8*P8/Assumptions!$B$20 -> 1050.2189 | U8: =IF(N8=0,0,L8/N8) -> 0.71767907
A9: P08 | B9: Mixer Grinder 750 W | C9: Kitchen Appliances | D9: 750 W universal motor, 3 stainless-steel jars | E9: WC07 | F9: =INDEX(WorkCentres!$C$2:$C$10,MATCH(E9,WorkCentres!$A$2:$A$10,0)) -> FA-2 Kitchen | G9: 250 | H9: 24 | I9: 14000 | J9: 195 | K9: Jar lids and gaskets, switch, overload protector, cord, rubber feet | L9: =SUMIFS(BOM!$K$2:$K$400,BOM!$B$2:$B$400,$A9) -> 1006.8588 | M9: =INDEX(Routing!$L$25:$L$39,MATCH($A9,Routing!$A$25:$A$39,0)) -> 160.72667 | N9: =L9+J9+M9 -> 1362.5855 | O9: 2005 | P9: =O9-N9 -> 642.41451 | Q9: =IF(O9=0,0,P9/O9) -> 0.32040624 | R9: =INDEX(Demand_Plan!$Q$24:$Q$38,MATCH($A9,Demand_Plan!$A$24:$A$38,0)) -> 169250 | S9: =R9*O9/Assumptions!$B$20 -> 3393.4625 | T9: =R9*P9/Assumptions!$B$20 -> 1087.2866 | U9: =IF(N9=0,0,L9/N9) -> 0.73893259
A10: P09 | B10: Electric Kettle 1.5 L | C10: Kitchen Appliances | D10: 1.5 L stainless-steel vessel, 1500 W concealed element | E10: WC07 | F10: =INDEX(WorkCentres!$C$2:$C$10,MATCH(E10,WorkCentres!$A$2:$A$10,0)) -> FA-2 Kitchen | G10: 500 | H10: 12 | I10: 22000 | J10: 140 | K10: Thermostat/cut-off controller, base connector, cord, switch and indicator | L10: =SUMIFS(BOM!$K$2:$K$400,BOM!$B$2:$B$400,$A10) -> 197.06726 | M10: =INDEX(Routing!$L$25:$L$39,MATCH($A10,Routing!$A$25:$A$39,0)) -> 56.378333 | N10: =L10+J10+M10 -> 393.4456 | O10: 560 | P10: =O10-N10 -> 166.5544 | Q10: =IF(O10=0,0,P10/O10) -> 0.29741858 | R10: =INDEX(Demand_Plan!$Q$24:$Q$38,MATCH($A10,Demand_Plan!$A$24:$A$38,0)) -> 266500 | S10: =R10*O10/Assumptions!$B$20 -> 1492.4 | T10: =R10*P10/Assumptions!$B$20 -> 443.86749 | U10: =IF(N10=0,0,L10/N10) -> 0.50087551
A11: P10 | B11: Induction Cooktop 2000 W | C11: Kitchen Appliances | D11: 2000 W induction, touch/push controls, glass top | E11: WC07 | F11: =INDEX(WorkCentres!$C$2:$C$10,MATCH(E11,WorkCentres!$A$2:$A$10,0)) -> FA-2 Kitchen | G11: 250 | H11: 12 | I11: 11000 | J11: 780 | K11: Control PCB with IGBT, ceramic glass plate, cooling fan, cord, controls | L11: =SUMIFS(BOM!$K$2:$K$400,BOM!$B$2:$B$400,$A11) -> 371.37702 | M11: =INDEX(Routing!$L$25:$L$39,MATCH($A11,Routing!$A$25:$A$39,0)) -> 104.565 | N11: =L11+J11+M11 -> 1255.942 | O11: 1795 | P11: =O11-N11 -> 539.05798 | Q11: =IF(O11=0,0,P11/O11) -> 0.30031085 | R11: =INDEX(Demand_Plan!$Q$24:$Q$38,MATCH($A11,Demand_Plan!$A$24:$A$38,0)) -> 133500 | S11: =R11*O11/Assumptions!$B$20 -> 2396.325 | T11: =R11*P11/Assumptions!$B$20 -> 719.64241 | U11: =IF(N11=0,0,L11/N11) -> 0.29569599
A12: P11 | B12: Sandwich Maker 750 W | C12: Kitchen Appliances | D12: 750 W, non-stick die-cast plates, 2-slice | E12: WC07 | F12: =INDEX(WorkCentres!$C$2:$C$10,MATCH(E12,WorkCentres!$A$2:$A$10,0)) -> FA-2 Kitchen | G12: 250 | H12: 12 | I12: 9500 | J12: 90 | K12: Thermostat, non-stick coating service, cord, indicator, rubber feet | L12: =SUMIFS(BOM!$K$2:$K$400,BOM!$B$2:$B$400,$A12) -> 302.83062 | M12: =INDEX(Routing!$L$25:$L$39,MATCH($A12,Routing!$A$25:$A$39,0)) -> 96.911667 | N12: =L12+J12+M12 -> 489.74229 | O12: 710 | P12: =O12-N12 -> 220.25771 | Q12: =IF(O12=0,0,P12/O12) -> 0.31022213 | R12: =INDEX(Demand_Plan!$Q$24:$Q$38,MATCH($A12,Demand_Plan!$A$24:$A$38,0)) -> 115500 | S12: =R12*O12/Assumptions!$B$20 -> 820.05 | T12: =R12*P12/Assumptions!$B$20 -> 254.39766 | U12: =IF(N12=0,0,L12/N12) -> 0.61834689
A13: P12 | B13: Fan Room Heater 2000 W | C13: Heating & Water | D13: 2000 W, 2 heat settings with fan, tip-over cut-off | E13: WC08 | F13: =INDEX(WorkCentres!$C$2:$C$10,MATCH(E13,WorkCentres!$A$2:$A$10,0)) -> FA-3 Heating & pumps | G13: 250 | H13: 12 | I13: 7000 | J13: 215 | K13: Thermal fuse and thermostat, switches, tip-over switch, cord | L13: =SUMIFS(BOM!$K$2:$K$400,BOM!$B$2:$B$400,$A13) -> 441.30176 | M13: =INDEX(Routing!$L$25:$L$39,MATCH($A13,Routing!$A$25:$A$39,0)) -> 114.39167 | N13: =L13+J13+M13 -> 770.69342 | O13: 1100 | P13: =O13-N13 -> 329.30658 | Q13: =IF(O13=0,0,P13/O13) -> 0.29936961 | R13: =INDEX(Demand_Plan!$Q$24:$Q$38,MATCH($A13,Demand_Plan!$A$24:$A$38,0)) -> 85250 | S13: =R13*O13/Assumptions!$B$20 -> 937.75 | T13: =R13*P13/Assumptions!$B$20 -> 280.73386 | U13: =IF(N13=0,0,L13/N13) -> 0.57260351
... A16: P15 | B16: Water Pump 0.5 HP Monoblock | C16: Heating & Water | D16: 0.5 HP (0.37 kW) single-phase monoblock centrifugal pump | E16: WC08 | F16: =INDEX(WorkCentres!$C$2:$C$10,MATCH(E16,WorkCentres!$A$2:$A$10,0)) -> FA-3 Heating & pumps | G16: 100 | H16: 24 | I16: 4500 | J16: 450 | K16: Mechanical seal, bearings, capacitor, terminal block, noryl impeller | L16: =SUMIFS(BOM!$K$2:$K$400,BOM!$B$2:$B$400,$A16) -> 1929.7305 | M16: =INDEX(Routing!$L$25:$L$39,MATCH($A16,Routing!$A$25:$A$39,0)) -> 260.14167 | N16: =L16+J16+M16 -> 2639.8721 | O16: 3565 | P16: =O16-N16 -> 925.12788 | Q16: =IF(O16=0,0,P16/O16) -> 0.25950291 | R16: =INDEX(Demand_Plan!$Q$24:$Q$38,MATCH($A16,Demand_Plan!$A$24:$A$38,0)) -> 54400 | S16: =R16*O16/Assumptions!$B$20 -> 1939.36 | T16: =R16*P16/Assumptions!$B$20 -> 503.26957 | U16: =IF(N16=0,0,L16/N16) -> 0.73099391
A18: Plant total | Q18: =IF(S18=0,0,T18/S18) -> 0.29587649 | R18: =SUM(R2:R16) -> 2620700 | S18: =SUM(S2:S16) -> 36387.618 | T18: =SUM(T2:T16) -> 10766.241 | U18: =IF(SUMPRODUCT(R2:R16,N2:N16)=0,0,SUMPRODUCT(R2:R16,L2:L16)/SUMPRODUCT(R2:R16,N2:N16)) -> 0.63064495
A20: Standard cost = raw material (from BOM) + bought-out parts + conversion (routing minutes x work-centre rate). Selling prices are planning ex-factory prices (before GST) chosen to give roughly 26-35% gross margin at base-case costs - replace with your actual price list.
A21: Bought-out parts (electronics, bearings, switches, glass, cords, etc.) are not among the 10 modelled raw materials; they are carried as a ₹ / unit allowance so unit costs stay realistic. Plant total margin and RM share are volume-weighted.

Sheet RawMaterials
A1: RM ID | B1: Raw material | C1: Short name | D1: Specification | E1: Category | F1: UoM | G1: Standard price (₹ / kg, weighted) | H1: Price change vs base (lever) | I1: Process yield (net ÷ gross) | J1: Weighted lead time (days) | K1: Longest lead time (days) | L1: Order lot (kg) = MOQ of main source | M1: Safety stock (days of usage) | N1: Price volatility | O1: Storage / handling | P1: Price basis & source note | Q1: Sources (#) | R1: Sole source? | S1: Import share of supply | T1: Source-share check (must = 100%)
A2: RW01 | B2: CRNGO Electrical Steel Coil | C2: CRNGO steel coil | D2: Non-oriented silicon steel, M-grade, 0.50 mm slit coil | E2: Ferrous metal | F2: kg | G2: =SUMPRODUCT((Sourcing!$B$2:$B$60=$A2)*Sourcing!$G$2:$G$60*Sourcing!$I$2:$I$60) -> 93.4 | H2: 0 | I2: 0.7 | J2: =SUMPRODUCT((Sourcing!$B$2:$B$60=$A2)*Sourcing!$G$2:$G$60*Sourcing!$J$2:$J$60) -> 16.8 | K2: =SUMPRODUCT(MAX((Sourcing!$B$2:$B$60=$A2)*Sourcing!$J$2:$J$60)) -> 21 | L2: =SUMIFS(Sourcing!$K$2:$K$60,Sourcing!$B$2:$B$60,$A2,Sourcing!$F$2:$F$60,"Primary")+SUMIFS(Sourcing!$K$2:$K$60,Sourcing!$B$2:$B$60,$A2,Sourcing!$F$2:$F$60,"Sole source") -> 10000 | M2: 7 | N2: Medium | O2: Covered coil store; rust-sensitive, oiled coils | P2: Planning estimate - no dated public quote found; CRNGO is sold on mill price lists | Q2: =COUNTIF(Sourcing!$B$2:$B$60,$A2) -> 2 | R2: =IF(Q2=1,"Yes","No") -> No | S2: =SUMPRODUCT((Sourcing!$B$2:$B$60=$A2)*(Sourcing!$M$2:$M$60<>"India")*Sourcing!$G$2:$G$60) -> 0 | T2: =SUMIF(Sourcing!$B$2:$B$60,$A2,Sourcing!$G$2:$G$60) -> 1
A3: RW02 | B3: CRCA Steel Sheet / Coil | C3: CRCA steel sheet | D3: Cold-rolled low-carbon steel sheet / coil, IS 513 type, 0.5-1.2 mm | E3: Ferrous metal | F3: kg | G3: =SUMPRODUCT((Sourcing!$B$2:$B$60=$A3)*Sourcing!$G$2:$G$60*Sourcing!$I$2:$I$60) -> 66.65 | H3: 0 | I3: 0.85 | J3: =SUMPRODUCT((Sourcing!$B$2:$B$60=$A3)*Sourcing!$G$2:$G$60*Sourcing!$J$2:$J$60) -> 10.85 | K3: =SUMPRODUCT(MAX((Sourcing!$B$2:$B$60=$A3)*Sourcing!$J$2:$J$60)) -> 18 | L3: =SUMIFS(Sourcing!$K$2:$K$60,Sourcing!$B$2:$B$60,$A3,Sourcing!$F$2:$F$60,"Primary")+SUMIFS(Sourcing!$K$2:$K$60,Sourcing!$B$2:$B$60,$A3,Sourcing!$F$2:$F$60,"Sole source") -> 3000 | M3: 7 | N3: Medium | O3: Covered sheet and coil store | P3: CR coil list rates ₹61.9-64.6k/t ex-yard (Tata nexarc page, dated 'Oct-24', year unclear) + ₹3-4/kg cut-to-length; rounded | Q3: =COUNTIF(Sourcing!$B$2:$B$60,$A3) -> 2 | R3: =IF(Q3=1,"Yes","No") -> No | S3: =SUMPRODUCT((Sourcing!$B$2:$B$60=$A3)*(Sourcing!$M$2:$M$60<>"India")*Sourcing!$G$2:$G$60) -> 0 | T3: =SUMIF(Sourcing!$B$2:$B$60,$A3,Sourcing!$G$2:$G$60) -> 1
A4: RW03 | B4: Aluminium Alloy Ingot (ADC12) | C4: Aluminium ADC12 | D4: ADC12 / A383 die-casting alloy, 10 kg bars | E4: Non-ferrous metal | F4: kg | G4: =SUMPRODUCT((Sourcing!$B$2:$B$60=$A4)*Sourcing!$G$2:$G$60*Sourcing!$I$2:$I$60) -> 261.5 | H4: 0 | I4: 0.92 | J4: =SUMPRODUCT((Sourcing!$B$2:$B$60=$A4)*Sourcing!$G$2:$G$60*Sourcing!$J$2:$J$60) -> 7.9 | K4: =SUMPRODUCT(MAX((Sourcing!$B$2:$B$60=$A4)*Sourcing!$J$2:$J$60)) -> 10 | L4: =SUMIFS(Sourcing!$K$2:$K$60,Sourcing!$B$2:$B$60,$A4,Sourcing!$F$2:$F$60,"Primary")+SUMIFS(Sourcing!$K$2:$K$60,Sourcing!$B$2:$B$60,$A4,Sourcing!$F$2:$F$60,"Sole source") -> 5000 | M4: 6 | N4: High | O4: Ingot yard next to melting furnace | P4: ADC12 benchmark ₹201-219/kg in late 2024 (BigMint via alcircle); scaled for 2026 LME and INR levels - estimate | Q4: =COUNTIF(Sourcing!$B$2:$B$60,$A4) -> 2 | R4: =IF(Q4=1,"Yes","No") -> No | S4: =SUMPRODUCT((Sourcing!$B$2:$B$60=$A4)*(Sourcing!$M$2:$M$60<>"India")*Sourcing!$G$2:$G$60) -> 0 | T4: =SUMIF(Sourcing!$B$2:$B$60,$A4,Sourcing!$G$2:$G$60) -> 1
A5: RW04 | B5: Enamelled Copper Winding Wire | C5: Copper winding wire | D5: Class 180 (H), 0.25-0.80 mm round wire on spools | E5: Non-ferrous metal | F5: kg | G5: =SUMPRODUCT((Sourcing!$B$2:$B$60=$A5)*Sourcing!$G$2:$G$60*Sourcing!$I$2:$I$60) -> 1336.25 | H5: 0 | I5: 0.98 | J5: =SUMPRODUCT((Sourcing!$B$2:$B$60=$A5)*Sourcing!$G$2:$G$60*Sourcing!$J$2:$J$60) -> 12.5 | K5: =SUMPRODUCT(MAX((Sourcing!$B$2:$B$60=$A5)*Sourcing!$J$2:$J$60)) -> 14 | L5: =SUMIFS(Sourcing!$K$2:$K$60,Sourcing!$B$2:$B$60,$A5,Sourcing!$F$2:$F$60,"Primary")+SUMIFS(Sourcing!$K$2:$K$60,Sourcing!$B$2:$B$60,$A5,Sourcing!$F$2:$F$60,"Sole source") -> 1000 | M5: 7 | N5: High | O5: Dry, covered spool racks; moisture-sensitive enamel | P5: Copper wire rod ₹1,229-1,249/kg ex-GST (OfBusiness listing) + about ₹100/kg enamelling premium (estimate) | Q5: =COUNTIF(Sourcing!$B$2:$B$60,$A5) -> 2 | R5: =IF(Q5=1,"Yes","No") -> No | S5: =SUMPRODUCT((Sourcing!$B$2:$B$60=$A5)*(Sourcing!$M$2:$M$60<>"India")*Sourcing!$G$2:$G$60) -> 0 | T5: =SUMIF(Sourcing!$B$2:$B$60,$A5,Sourcing!$G$2:$G$60) -> 1
A6: RW05 | B6: Polypropylene (PP) Granules | C6: PP granules | D6: Injection-moulding grade PP, homopolymer/copolymer, 25 kg bags | E6: Polymer | F6: kg | G6: =SUMPRODUCT((Sourcing!$B$2:$B$60=$A6)*Sourcing!$G$2:$G$60*Sourcing!$I$2:$I$60) -> 107 | H6: 0 | I6: 0.97 | J6: =SUMPRODUCT((Sourcing!$B$2:$B$60=$A6)*Sourcing!$G$2:$G$60*Sourcing!$J$2:$J$60) -> 12.4 | K6: =SUMPRODUCT(MAX((Sourcing!$B$2:$B$60=$A6)*Sourcing!$J$2:$J$60)) -> 38 | L6: =SUMIFS(Sourcing!$K$2:$K$60,Sourcing!$B$2:$B$60,$A6,Sourcing!$F$2:$F$60,"Primary")+SUMIFS(Sourcing!$K$2:$K$60,Sourcing!$B$2:$B$60,$A6,Sourcing!$F$2:$F$60,"Sole source") -> 5000 | M6: 12 | N6: Medium | O6: Dry bagged store; hopper-dryer feed | P6: Mumbai PP list (PolymerUpdate) needs a login - planning estimate | Q6: =COUNTIF(Sourcing!$B$2:$B$60,$A6) -> 2 | R6: =IF(Q6=1,"Yes","No") -> No | S6: =SUMPRODUCT((Sourcing!$B$2:$B$60=$A6)*(Sourcing!$M$2:$M$60<>"India")*Sourcing!$G$2:$G$60) -> 0.2 | T6: =SUMIF(Sourcing!$B$2:$B$60,$A6,Sourcing!$G$2:$G$60) -> 1
A7: RW06 | B7: ABS Granules | C7: ABS granules | D7: General-purpose injection grade ABS, natural/black, 25 kg bags | E7: Polymer | F7: kg | G7: =SUMPRODUCT((Sourcing!$B$2:$B$60=$A7)*Sourcing!$G$2:$G$60*Sourcing!$I$2:$I$60) -> 156 | H7: 0 | I7: 0.97 | J7: =SUMPRODUCT((Sourcing!$B$2:$B$60=$A7)*Sourcing!$G$2:$G$60*Sourcing!$J$2:$J$60) -> 25.2 | K7: =SUMPRODUCT(MAX((Sourcing!$B$2:$B$60=$A7)*Sourcing!$J$2:$J$60)) -> 38 | L7: =SUMIFS(Sourcing!$K$2:$K$60,Sourcing!$B$2:$B$60,$A7,Sourcing!$F$2:$F$60,"Primary")+SUMIFS(Sourcing!$K$2:$K$60,Sourcing!$B$2:$B$60,$A7,Sourcing!$F$2:$F$60,"Sole source") -> 20000 | M7: 14 | N7: Medium | O7: Dry bagged store; pre-dried before moulding | P7: Listings ₹140-170/kg (OfBusiness, undated); rounded | Q7: =COUNTIF(Sourcing!$B$2:$B$60,$A7) -> 2 | R7: =IF(Q7=1,"Yes","No") -> No | S7: =SUMPRODUCT((Sourcing!$B$2:$B$60=$A7)*(Sourcing!$M$2:$M$60<>"India")*Sourcing!$G$2:$G$60) -> 0.6 | T7: =SUMIF(Sourcing!$B$2:$B$60,$A7,Sourcing!$G$2:$G$60) -> 1
A8: RW07 | B8: Stainless Steel 304 Sheet | C8: SS304 sheet | D8: SS 304, 2B finish, 0.6-1.0 mm sheet | E8: Ferrous metal (stainless) | F8: kg | G8: =SUMPRODUCT((Sourcing!$B$2:$B$60=$A8)*Sourcing!$G$2:$G$60*Sourcing!$I$2:$I$60) -> 206.5 | H8: 0 | I8: 0.82 | J8: =SUMPRODUCT((Sourcing!$B$2:$B$60=$A8)*Sourcing!$G$2:$G$60*Sourcing!$J$2:$J$60) -> 5.2 | K8: =SUMPRODUCT(MAX((Sourcing!$B$2:$B$60=$A8)*Sourcing!$J$2:$J$60)) -> 7 | L8: =SUMIFS(Sourcing!$K$2:$K$60,Sourcing!$B$2:$B$60,$A8,Sourcing!$F$2:$F$60,"Primary")+SUMIFS(Sourcing!$K$2:$K$60,Sourcing!$B$2:$B$60,$A8,Sourcing!$F$2:$F$60,"Sole source") -> 1000 | M8: 7 | N8: High | O8: Covered sheet rack; film-protected surface | P8: Listings ₹180-220/kg, 2B sheet ₹190-210/kg (OfBusiness, undated); rounded | Q8: =COUNTIF(Sourcing!$B$2:$B$60,$A8) -> 2 | R8: =IF(Q8=1,"Yes","No") -> No | S8: =SUMPRODUCT((Sourcing!$B$2:$B$60=$A8)*(Sourcing!$M$2:$M$60<>"India")*Sourcing!$G$2:$G$60) -> 0 | T8: =SUMIF(Sourcing!$B$2:$B$60,$A8,Sourcing!$G$2:$G$60) -> 1
A9: RW08 | B9: Nichrome Resistance Wire (Ni80/Cr20) | C9: Nichrome wire | D9: Ni80Cr20 heating wire/ribbon, 0.3-1.2 mm | E9: Alloy | F9: kg | G9: =SUMPRODUCT((Sourcing!$B$2:$B$60=$A9)*Sourcing!$G$2:$G$60*Sourcing!$I$2:$I$60) -> 2080 | H9: 0 | I9: 0.96 | J9: =SUMPRODUCT((Sourcing!$B$2:$B$60=$A9)*Sourcing!$G$2:$G$60*Sourcing!$J$2:$J$60) -> 12.3 | K9: =SUMPRODUCT(MAX((Sourcing!$B$2:$B$60=$A9)*Sourcing!$J$2:$J$60)) -> 15 | L9: =SUMIFS(Sourcing!$K$2:$K$60,Sourcing!$B$2:$B$60,$A9,Sourcing!$F$2:$F$60,"Primary")+SUMIFS(Sourcing!$K$2:$K$60,Sourcing!$B$2:$B$60,$A9,Sourcing!$F$2:$F$60,"Sole source") -> 100 | M9: 15 | N9: High | O9: Locked store; high value per kg | P9: Seller listings ₹2,000-2,100/kg for coil-form 80/20 wire (IndiaMART); rounded | Q9: =COUNTIF(Sourcing!$B$2:$B$60,$A9) -> 2 | R9: =IF(Q9=1,"Yes","No") -> No | S9: =SUMPRODUCT((Sourcing!$B$2:$B$60=$A9)*(Sourcing!$M$2:$M$60<>"India")*Sourcing!$G$2:$G$60) -> 0 | T9: =SUMIF(Sourcing!$B$2:$B$60,$A9,Sourcing!$G$2:$G$60) -> 1
A10: RW09 | B10: Powder Coating (Epoxy-Polyester) | C10: Powder coating | D10: Hybrid powder, gloss/textured, 20 kg boxes | E10: Coating | F10: kg | G10: =SUMPRODUCT((Sourcing!$B$2:$B$60=$A10)*Sourcing!$G$2:$G$60*Sourcing!$I$2:$I$60) -> 345 | H10: 0 | I10: 0.8 | J10: =SUMPRODUCT((Sourcing!$B$2:$B$60=$A10)*Sourcing!$G$2:$G$60*Sourcing!$J$2:$J$60) -> 9 | K10: =SUMPRODUCT(MAX((Sourcing!$B$2:$B$60=$A10)*Sourcing!$J$2:$J$60)) -> 9 | L10: =SUMIFS(Sourcing!$K$2:$K$60,Sourcing!$B$2:$B$60,$A10,Sourcing!$F$2:$F$60,"Primary")+SUMIFS(Sourcing!$K$2:$K$60,Sourcing!$B$2:$B$60,$A10,Sourcing!$F$2:$F$60,"Sole source") -> 500 | M10: 10 | N10: Medium | O10: Cool dry store; shelf life 12 months | P10: Planning estimate - retail listings not extracted | Q10: =COUNTIF(Sourcing!$B$2:$B$60,$A10) -> 1 | R10: =IF(Q10=1,"Yes","No") -> Yes | S10: =SUMPRODUCT((Sourcing!$B$2:$B$60=$A10)*(Sourcing!$M$2:$M$60<>"India")*Sourcing!$G$2:$G$60) -> 0 | T10: =SUMIF(Sourcing!$B$2:$B$60,$A10,Sourcing!$G$2:$G$60) -> 1
A11: RW10 | B11: Corrugated Board / Cartons | C11: Corrugated cartons | D11: 5-ply printed cartons with die-cut inserts, priced per kg of board | E11: Packaging | F11: kg | G11: =SUMPRODUCT((Sourcing!$B$2:$B$60=$A11)*Sourcing!$G$2:$G$60*Sourcing!$I$2:$I$60) -> 52 | H11: 0 | I11: 0.97 | J11: =SUMPRODUCT((Sourcing!$B$2:$B$60=$A11)*Sourcing!$G$2:$G$60*Sourcing!$J$2:$J$60) -> 6 | K11: =SUMPRODUCT(MAX((Sourcing!$B$2:$B$60=$A11)*Sourcing!$J$2:$J$60)) -> 6 | L11: =SUMIFS(Sourcing!$K$2:$K$60,Sourcing!$B$2:$B$60,$A11,Sourcing!$F$2:$F$60,"Primary")+SUMIFS(Sourcing!$K$2:$K$60,Sourcing!$B$2:$B$60,$A11,Sourcing!$F$2:$F$60,"Sole source") -> 2000 | M11: 7 | N11: Low | O11: Covered flat-pack store; humidity-sensitive | P11: Planning estimate (kraft board + converting) | Q11: =COUNTIF(Sourcing!$B$2:$B$60,$A11) -> 1 | R11: =IF(Q11=1,"Yes","No") -> Yes | S11: =SUMPRODUCT((Sourcing!$B$2:$B$60=$A11)*(Sourcing!$M$2:$M$60<>"India")*Sourcing!$G$2:$G$60) -> 0 | T11: =SUMIF(Sourcing!$B$2:$B$60,$A11,Sourcing!$G$2:$G$60) -> 1
A13: All quantities are in kg so the BOM is on one consistent basis. Standard price = share-weighted effective price across the sources on the Sourcing sheet (quoted price x (1 + price change)).
A14: Prices are indicative planning rates in ₹ per kg ex-GST, anchored to public listings where marked and otherwise estimated. They are not supplier quotes - see the README for what is calculated, estimated or sourced.

Sheet Suppliers
A1: Supplier ID | B1: Supplier (fictional) | C1: Short name | D1: City / state | E1: Country | F1: Supplier type | G1: Certifications | H1: On-time delivery (OTD) | I1: Avg delay when late (days) | J1: Rejection rate | K1: Lead-time std dev (days) | L1: Financial health score (0-100) | M1: Payment terms (days) | N1: Materials supplied (#) | O1: Sole-source materials (#) | P1: Avg lead time (days) | Q1: Annual spend (₹ lakh) | R1: Share of RM spend | S1: Domestic / import | T1: Risk flags (#) | U1: Watch-list reasons
A2: S01 | B2: Kalinga Electrical Steels Pvt Ltd | C2: Kalinga Steels | D2: Rourkela, Odisha | E2: India | F2: Steel mill | G2: ISO 9001, ISO 14001, BIS licence | H2: 0.91 | I2: 4.5 | J2: 0.008 | K2: 4 | L2: 84 | M2: 21 | N2: =COUNTIF(Sourcing!$D$2:$D$60,$A2) -> 2 | O2: =COUNTIFS(Sourcing!$D$2:$D$60,$A2,Sourcing!$F$2:$F$60,"Sole source") -> 0 | P2: =IFERROR(AVERAGEIF(Sourcing!$D$2:$D$60,$A2,Sourcing!$J$2:$J$60),0) -> 19.5 | Q2: =INDEX(Spend!$M$5:$M$14,MATCH($A2,Spend!$A$5:$A$14,0)) -> 1540.7753 | R2: =IF(SUM($Q$2:$Q$11)=0,0,Q2/SUM($Q$2:$Q$11)) -> 0.095356855 | S2: =IF(E2="India","Domestic","Import") -> Domestic | T2: =(H2<Assumptions!$B$15)+(O2>0)+(S2="Import")+(L2<Assumptions!$B$16)+(R2>=Assumptions!$B$17) -> 0 | U2: =IF(T2=0,"None",MID(IF(H2<Assumptions!$B$15,"; Low on-time delivery","")&IF(O2>0,"; Sole source for "&O2&" material(s)","")&IF(S2="Import","; Import / long lead time","")&IF(L2<Assumptions!$B$16,"; Weak financial score","")&IF(R2>=Assumptions!$B$17,"; High share of RM spend",""),3,200)) -> None
A3: S02 | B3: Pune Coil Processing Pvt Ltd | C3: Pune Coil Proc. | D3: Chakan, Pune, Maharashtra | E3: India | F3: Steel service centre | G3: ISO 9001 | H3: 0.955 | I3: 2 | J3: 0.009 | K3: 2 | L3: 74 | M3: 45 | N3: =COUNTIF(Sourcing!$D$2:$D$60,$A3) -> 3 | O3: =COUNTIFS(Sourcing!$D$2:$D$60,$A3,Sourcing!$F$2:$F$60,"Sole source") -> 0 | P3: =IFERROR(AVERAGEIF(Sourcing!$D$2:$D$60,$A3,Sourcing!$J$2:$J$60),0) -> 6.3333333 | Q3: =INDEX(Spend!$M$5:$M$14,MATCH($A3,Spend!$A$5:$A$14,0)) -> 1813.1851 | R3: =IF(SUM($Q$2:$Q$11)=0,0,Q3/SUM($Q$2:$Q$11)) -> 0.11221599 | S3: =IF(E3="India","Domestic","Import") -> Domestic | T3: =(H3<Assumptions!$B$15)+(O3>0)+(S3="Import")+(L3<Assumptions!$B$16)+(R3>=Assumptions!$B$17) -> 0 | U3: =IF(T3=0,"None",MID(IF(H3<Assumptions!$B$15,"; Low on-time delivery","")&IF(O3>0,"; Sole source for "&O3&" material(s)","")&IF(S3="Import","; Import / long lead time","")&IF(L3<Assumptions!$B$16,"; Weak financial score","")&IF(R3>=Assumptions!$B$17,"; High share of RM spend",""),3,200)) -> None
A4: S03 | B4: Deccan Aluminium Alloys Ltd | C4: Deccan Aluminium | D4: Hyderabad, Telangana | E4: India | F4: Secondary aluminium smelter | G4: ISO 9001, IATF 16949 | H4: 0.9 | I4: 3.5 | J4: 0.014 | K4: 3 | L4: 69 | M4: 30 | N4: =COUNTIF(Sourcing!$D$2:$D$60,$A4) -> 1 | O4: =COUNTIFS(Sourcing!$D$2:$D$60,$A4,Sourcing!$F$2:$F$60,"Sole source") -> 0 | P4: =IFERROR(AVERAGEIF(Sourcing!$D$2:$D$60,$A4,Sourcing!$J$2:$J$60),0) -> 10 | Q4: =INDEX(Spend!$M$5:$M$14,MATCH($A4,Spend!$A$5:$A$14,0)) -> 1453.5033 | R4: =IF(SUM($Q$2:$Q$11)=0,0,Q4/SUM($Q$2:$Q$11)) -> 0.089955688 | S4: =IF(E4="India","Domestic","Import") -> Domestic | T4: =(H4<Assumptions!$B$15)+(O4>0)+(S4="Import")+(L4<Assumptions!$B$16)+(R4>=Assumptions!$B$17) -> 0 | U4: =IF(T4=0,"None",MID(IF(H4<Assumptions!$B$15,"; Low on-time delivery","")&IF(O4>0,"; Sole source for "&O4&" material(s)","")&IF(S4="Import","; Import / long lead time","")&IF(L4<Assumptions!$B$16,"; Weak financial score","")&IF(R4>=Assumptions!$B$17,"; High share of RM spend",""),3,200)) -> None
A5: S04 | B5: Bharat Metal Traders | C5: Bharat Metal Traders | D5: Mumbai, Maharashtra | E5: India | F5: Metal trader / stockist | G5: GST-registered trader (no plant certification) | H5: 0.93 | I5: 2.5 | J5: 0.011 | K5: 2.5 | L5: 61 | M5: 15 | N5: =COUNTIF(Sourcing!$D$2:$D$60,$A5) -> 3 | O5: =COUNTIFS(Sourcing!$D$2:$D$60,$A5,Sourcing!$F$2:$F$60,"Sole source") -> 0 | P5: =IFERROR(AVERAGEIF(Sourcing!$D$2:$D$60,$A5,Sourcing!$J$2:$J$60),0) -> 4.3333333 | Q5: =INDEX(Spend!$M$5:$M$14,MATCH($A5,Spend!$A$5:$A$14,0)) -> 1417.5745 | R5: =IF(SUM($Q$2:$Q$11)=0,0,Q5/SUM($Q$2:$Q$11)) -> 0.087732097 | S5: =IF(E5="India","Domestic","Import") -> Domestic | T5: =(H5<Assumptions!$B$15)+(O5>0)+(S5="Import")+(L5<Assumptions!$B$16)+(R5>=Assumptions!$B$17) -> 1 | U5: =IF(T5=0,"None",MID(IF(H5<Assumptions!$B$15,"; Low on-time delivery","")&IF(O5>0,"; Sole source for "&O5&" material(s)","")&IF(S5="Import","; Import / long lead time","")&IF(L5<Assumptions!$B$16,"; Weak financial score","")&IF(R5>=Assumptions!$B$17,"; High share of RM spend",""),3,200)) -> Weak financial score
A6: S05 | B6: Vadodara Winding & Resistance Wires Ltd | C6: Vadodara Wires | D6: Vadodara, Gujarat | E6: India | F6: Winding & resistance wire maker | G6: ISO 9001, ISO 14001 | H6: 0.96 | I6: 1.5 | J6: 0.003 | K6: 1.5 | L6: 78 | M6: 45 | N6: =COUNTIF(Sourcing!$D$2:$D$60,$A6) -> 2 | O6: =COUNTIFS(Sourcing!$D$2:$D$60,$A6,Sourcing!$F$2:$F$60,"Sole source") -> 0 | P6: =IFERROR(AVERAGEIF(Sourcing!$D$2:$D$60,$A6,Sourcing!$J$2:$J$60),0) -> 13.5 | Q6: =INDEX(Spend!$M$5:$M$14,MATCH($A6,Spend!$A$5:$A$14,0)) -> 5291.3933 | R6: =IF(SUM($Q$2:$Q$11)=0,0,Q6/SUM($Q$2:$Q$11)) -> 0.32747839 | S6: =IF(E6="India","Domestic","Import") -> Domestic | T6: =(H6<Assumptions!$B$15)+(O6>0)+(S6="Import")+(L6<Assumptions!$B$16)+(R6>=Assumptions!$B$17) -> 1 | U6: =IF(T6=0,"None",MID(IF(H6<Assumptions!$B$15,"; Low on-time delivery","")&IF(O6>0,"; Sole source for "&O6&" material(s)","")&IF(S6="Import","; Import / long lead time","")&IF(L6<Assumptions!$B$16,"; Weak financial score","")&IF(R6>=Assumptions!$B$17,"; High share of RM spend",""),3,200)) -> High share of RM spend
A7: S06 | B7: Coimbatore Magnet Wires Pvt Ltd | C7: Coimbatore Magnet | D7: Coimbatore, Tamil Nadu | E7: India | F7: Winding wire maker | G7: ISO 9001 | H7: 0.885 | I7: 4 | J7: 0.007 | K7: 3.5 | L7: 66 | M7: 45 | N7: =COUNTIF(Sourcing!$D$2:$D$60,$A7) -> 1 | O7: =COUNTIFS(Sourcing!$D$2:$D$60,$A7,Sourcing!$F$2:$F$60,"Sole source") -> 0 | P7: =IFERROR(AVERAGEIF(Sourcing!$D$2:$D$60,$A7,Sourcing!$J$2:$J$60),0) -> 14 | Q7: =INDEX(Spend!$M$5:$M$14,MATCH($A7,Spend!$A$5:$A$14,0)) -> 1689.545 | R7: =IF(SUM($Q$2:$Q$11)=0,0,Q7/SUM($Q$2:$Q$11)) -> 0.10456405 | S7: =IF(E7="India","Domestic","Import") -> Domestic | T7: =(H7<Assumptions!$B$15)+(O7>0)+(S7="Import")+(L7<Assumptions!$B$16)+(R7>=Assumptions!$B$17) -> 1 | U7: =IF(T7=0,"None",MID(IF(H7<Assumptions!$B$15,"; Low on-time delivery","")&IF(O7>0,"; Sole source for "&O7&" material(s)","")&IF(S7="Import","; Import / long lead time","")&IF(L7<Assumptions!$B$16,"; Weak financial score","")&IF(R7>=Assumptions!$B$17,"; High share of RM spend",""),3,200)) -> Low on-time delivery
A8: S07 | B8: Mumbai Polymer Distribution Co. | C8: Mumbai Polymer | D8: Navi Mumbai, Maharashtra | E8: India | F8: Polymer distributor | G8: ISO 9001 | H8: 0.945 | I8: 2 | J8: 0.004 | K8: 2 | L8: 85 | M8: 30 | N8: =COUNTIF(Sourcing!$D$2:$D$60,$A8) -> 2 | O8: =COUNTIFS(Sourcing!$D$2:$D$60,$A8,Sourcing!$F$2:$F$60,"Sole source") -> 0 | P8: =IFERROR(AVERAGEIF(Sourcing!$D$2:$D$60,$A8,Sourcing!$J$2:$J$60),0) -> 6 | Q8: =INDEX(Spend!$M$5:$M$14,MATCH($A8,Spend!$A$5:$A$14,0)) -> 1066.9995 | R8: =IF(SUM($Q$2:$Q$11)=0,0,Q8/SUM($Q$2:$Q$11)) -> 0.066035401 | S8: =IF(E8="India","Domestic","Import") -> Domestic | T8: =(H8<Assumptions!$B$15)+(O8>0)+(S8="Import")+(L8<Assumptions!$B$16)+(R8>=Assumptions!$B$17) -> 0 | U8: =IF(T8=0,"None",MID(IF(H8<Assumptions!$B$15,"; Low on-time delivery","")&IF(O8>0,"; Sole source for "&O8&" material(s)","")&IF(S8="Import","; Import / long lead time","")&IF(L8<Assumptions!$B$16,"; Weak financial score","")&IF(R8>=Assumptions!$B$17,"; High share of RM spend",""),3,200)) -> None
A9: S08 | B9: Pacific Engineering Plastics Co. Ltd | C9: Pacific Plastics (TW) | D9: Kaohsiung | E9: Taiwan | F9: Resin producer (import) | G9: ISO 9001, ISO 14001 | H9: 0.86 | I9: 6.5 | J9: 0.005 | K9: 7 | L9: 88 | M9: 60 | N9: =COUNTIF(Sourcing!$D$2:$D$60,$A9) -> 2 | O9: =COUNTIFS(Sourcing!$D$2:$D$60,$A9,Sourcing!$F$2:$F$60,"Sole source") -> 0 | P9: =IFERROR(AVERAGEIF(Sourcing!$D$2:$D$60,$A9,Sourcing!$J$2:$J$60),0) -> 38 | Q9: =INDEX(Spend!$M$5:$M$14,MATCH($A9,Spend!$A$5:$A$14,0)) -> 775.4432 | R9: =IF(SUM($Q$2:$Q$11)=0,0,Q9/SUM($Q$2:$Q$11)) -> 0.04799131 | S9: =IF(E9="India","Domestic","Import") -> Import | T9: =(H9<Assumptions!$B$15)+(O9>0)+(S9="Import")+(L9<Assumptions!$B$16)+(R9>=Assumptions!$B$17) -> 2 | U9: =IF(T9=0,"None",MID(IF(H9<Assumptions!$B$15,"; Low on-time delivery","")&IF(O9>0,"; Sole source for "&O9&" material(s)","")&IF(S9="Import","; Import / long lead time","")&IF(L9<Assumptions!$B$16,"; Weak financial score","")&IF(R9>=Assumptions!$B$17,"; High share of RM spend",""),3,200)) -> Low on-time delivery; Import / long lead time
A10: S09 | B10: Ahmedabad Coatings & Powders Pvt Ltd | C10: Ahmedabad Coatings | D10: Ahmedabad, Gujarat | E10: India | F10: Powder-coating manufacturer | G10: ISO 9001 | H10: 0.925 | I10: 3 | J10: 0.006 | K10: 2.5 | L10: 58 | M10: 45 | N10: =COUNTIF(Sourcing!$D$2:$D$60,$A10) -> 1 | O10: =COUNTIFS(Sourcing!$D$2:$D$60,$A10,Sourcing!$F$2:$F$60,"Sole source") -> 1 | P10: =IFERROR(AVERAGEIF(Sourcing!$D$2:$D$60,$A10,Sourcing!$J$2:$J$60),0) -> 9 | Q10: =INDEX(Spend!$M$5:$M$14,MATCH($A10,Spend!$A$5:$A$14,0)) -> 314.24756 | R10: =IF(SUM($Q$2:$Q$11)=0,0,Q10/SUM($Q$2:$Q$11)) -> 0.019448429 | S10: =IF(E10="India","Domestic","Import") -> Domestic | T10: =(H10<Assumptions!$B$15)+(O10>0)+(S10="Import")+(L10<Assumptions!$B$16)+(R10>=Assumptions!$B$17) -> 2 | U10: =IF(T10=0,"None",MID(IF(H10<Assumptions!$B$15,"; Low on-time delivery","")&IF(O10>0,"; Sole source for "&O10&" material(s)","")&IF(S10="Import","; Import / long lead time","")&IF(L10<Assumptions!$B$16,"; Weak financial score","")&IF(R10>=Assumptions!$B$17,"; High share of RM spend",""),3,200)) -> Sole source for 1 material(s); Weak financial score
A11: S10 | B11: Bhiwandi Packaging Industries | C11: Bhiwandi Packaging | D11: Bhiwandi, Maharashtra | E11: India | F11: Corrugated carton converter | G11: ISO 9001, FSC chain of custody | H11: 0.97 | I11: 1 | J11: 0.009 | K11: 1 | L11: 72 | M11: 60 | N11: =COUNTIF(Sourcing!$D$2:$D$60,$A11) -> 1 | O11: =COUNTIFS(Sourcing!$D$2:$D$60,$A11,Sourcing!$F$2:$F$60,"Sole source") -> 1 | P11: =IFERROR(AVERAGEIF(Sourcing!$D$2:$D$60,$A11,Sourcing!$J$2:$J$60),0) -> 6 | Q11: =INDEX(Spend!$M$5:$M$14,MATCH($A11,Spend!$A$5:$A$14,0)) -> 795.32526 | R11: =IF(SUM($Q$2:$Q$11)=0,0,Q11/SUM($Q$2:$Q$11)) -> 0.049221788 | S11: =IF(E11="India","Domestic","Import") -> Domestic | T11: =(H11<Assumptions!$B$15)+(O11>0)+(S11="Import")+(L11<Assumptions!$B$16)+(R11>=Assumptions!$B$17) -> 1 | U11: =IF(T11=0,"None",MID(IF(H11<Assumptions!$B$15,"; Low on-time delivery","")&IF(O11>0,"; Sole source for "&O11&" material(s)","")&IF(S11="Import","; Import / long lead time","")&IF(L11<Assumptions!$B$16,"; Weak financial score","")&IF(R11>=Assumptions!$B$17,"; High share of RM spend",""),3,200)) -> Sole source for 1 material(s)
A13: Performance figures (OTD, delay, rejection, lead-time variability, financial score, payment terms) are illustrative planning inputs for fictional suppliers - not measured data. Flags use the thresholds on the Assumptions sheet.
A14: Annual spend comes from the Spend sheet (MRP volume x source split x effective price). Watch-list reasons are generated by formula, so they update when inputs change.

Sheet Sourcing
A1: Link ID | B1: RM ID | C1: Raw material | D1: Supplier ID | E1: Supplier | F1: Role | G1: Share of requirement | H1: Quoted price (₹ / kg) | I1: Effective price (₹ / kg) | J1: Lead time (days) | K1: MOQ (kg) | L1: Transport | M1: Supplier origin | N1: Annual volume (kg) | O1: Annual spend (₹ lakh) | Q1: Notes
A2: L01 | B2: RW01 | C2: =INDEX(RawMaterials!$B$2:$B$11,MATCH($B2,RawMaterials!$A$2:$A$11,0)) -> CRNGO Electrical Steel Coil | D2: S01 | E2: =INDEX(Suppliers!$B$2:$B$11,MATCH($D2,Suppliers!$A$2:$A$11,0)) -> Kalinga Electrical Steels Pvt Ltd | F2: Primary | G2: 0.7 | H2: 91 | I2: =H2*(1+INDEX(RawMaterials!$H$2:$H$11,MATCH($B2,RawMaterials!$A$2:$A$11,0))) -> 91 | J2: 21 | K2: 10000 | L2: Rail + road | M2: =INDEX(Suppliers!$E$2:$E$11,MATCH($D2,Suppliers!$A$2:$A$11,0)) -> India | N2: =G2*INDEX(MRP!$P$5:$P$14,MATCH($B2,MRP!$A$5:$A$14,0)) -> 940693.5 | O2: =N2*I2/Assumptions!$B$20 -> 856.03108 | Q2: Each material is bought from 1-2 sources. Share of requirement must add to 100% per material (see Checks). Role 'Sole source' = only one approved supplier. Annual volume = share x annual gross requirement from MRP; annual spend = volume x effective price. Quoted prices are indicative planning rates (ex-GST, delivered), not supplier quotes. Lead times and MOQs are typical for each supplier type. To add a sourcing link, type it in the next free row (formulas read rows 2-60) and copy the formulas in columns C, E, I, M, N and O down.
A3: L02 | B3: RW01 | C3: =INDEX(RawMaterials!$B$2:$B$11,MATCH($B3,RawMaterials!$A$2:$A$11,0)) -> CRNGO Electrical Steel Coil | D3: S02 | E3: =INDEX(Suppliers!$B$2:$B$11,MATCH($D3,Suppliers!$A$2:$A$11,0)) -> Pune Coil Processing Pvt Ltd | F3: Secondary | G3: 0.3 | H3: 99 | I3: =H3*(1+INDEX(RawMaterials!$H$2:$H$11,MATCH($B3,RawMaterials!$A$2:$A$11,0))) -> 99 | J3: 7 | K3: 2000 | L3: Road | M3: =INDEX(Suppliers!$E$2:$E$11,MATCH($D3,Suppliers!$A$2:$A$11,0)) -> India | N3: =G3*INDEX(MRP!$P$5:$P$14,MATCH($B3,MRP!$A$5:$A$14,0)) -> 403154.36 | O3: =N3*I3/Assumptions!$B$20 -> 399.12281
A4: L03 | B4: RW02 | C4: =INDEX(RawMaterials!$B$2:$B$11,MATCH($B4,RawMaterials!$A$2:$A$11,0)) -> CRCA Steel Sheet / Coil | D4: S02 | E4: =INDEX(Suppliers!$B$2:$B$11,MATCH($D4,Suppliers!$A$2:$A$11,0)) -> Pune Coil Processing Pvt Ltd | F4: Primary | G4: 0.55 | H4: 68 | I4: =H4*(1+INDEX(RawMaterials!$H$2:$H$11,MATCH($B4,RawMaterials!$A$2:$A$11,0))) -> 68 | J4: 5 | K4: 3000 | L4: Road | M4: =INDEX(Suppliers!$E$2:$E$11,MATCH($D4,Suppliers!$A$2:$A$11,0)) -> India | N4: =G4*INDEX(MRP!$P$5:$P$14,MATCH($B4,MRP!$A$5:$A$14,0)) -> 1287553.2 | O4: =N4*I4/Assumptions!$B$20 -> 875.5362
